Workbook
Name Macrobond_Object1: Downloads_dagcijfers!$A$3:$B$9233
Name Macrobond_Object1: Downloads_maandcijfers!$A$3:$CJ$513
Name Macrobond_Object1: downloads_saffier!$A$4:$E$163
Name Macrobond_Object1: Saffier_futures_cijfers!$A$4:$Y$111
Name Macrobond_Object2: Downloads_kwartaalcijfers!$A$3:$AE$317

Sheet Downloads_maandcijfers
B4: United States, Crude Oil, Brent Europe Spot Price FOB, USD | C4: Euro Area, FX Spot Rates, Macrobond, EUR per USD | D4: United States, Economic Policy Uncertainty, Economic Policy Uncertainty Indices, Headline Index, Index | E4: Europe, Economic Policy Uncertainty, Economic Policy Uncertainty Indices, News Based Index, Index | F4: United States, Volatility Indices, CBOE, S&P 500 Volatility Index (VIX), Close | G4: Germany, Government Benchmarks, Government Bond, 10 Year, Yield | H4: United States, Government Benchmarks, Federal Reserve, 10 Year, Yield | I4: Italy, Government Benchmarks, Macrobond, 10 Year, Yield | J4: Netherlands, Government Benchmarks, Macrobond, 10 Year, Yield | K4: Euro Area 20, Eurostat, HICP, All-Items HICP, 2015=100, Index | L4: Euro Area 20, Eurostat, HICP, Food Including Alcohol & Tobacco, 2015=100, Index | M4: Euro Area 20, Eurostat, HICP, Energy, 2015=100, Index | N4: Euro Area 20, Eurostat, HICP, Overall Index Excluding Energy, Food, Alcohol & Tobacco, 2015=100, Index | O4: Euro Area, Foreign Trade, CPB World Trade Monitor, Import, Volume, SA, Index | P4: Euro Area, Foreign Trade, CPB World Trade Monitor, Export, Volume, SA, Index | Q4: Euro Area, Business Surveys, S&P Global, Composite, Composite PMI Output Index, SA, Index | R4: Euro Area, Business Surveys, S&P Global, Manufacturing, Manufacturing PMI, SA, Index | S4: Euro Area, Business Surveys, S&P Global, Services, Services PMI Business Activity Index, SA, Index | T4: Euro Area, Business Surveys, S&P Global, Construction, Construction PMI Total Activity Index, SA, Index | U4: Euro Area, Consumer Surveys, DG ECFIN, Consumer Confidence, Balance, SA | V4: Euro Area, Business Surveys, DG ECFIN, Business Climate, Indicator (BCI), SA | W4: Euro Area, Business Surveys, DG ECFIN, Services Confidence Indicator, Total Service Sector, Balance, SA | X4: Euro Area, Business Surveys, DG ECFIN, Industrial Confidence Indicator, Total Sector, Monthly, Balance, SA | Y4: Euro Area, Business Surveys, DG ECFIN, Construction Confidence Indicator, Balance, SA | Z4: World, Baltic Exchange, Shipping, Dry Index (BDI), USD | AA4: World, Harper Petersen, Shipping, Harpex, Index, USD | AB4: World, Drewry Shipping Consultants Ltd, Shipping, Composite, Index | AC4: Netherlands, Equity Indices, Euronext Amsterdam, AEX-Index, Price Return, Close, EUR | AD4: United States, Equity Indices, S&P, 500, Index, Price Return, Close, USD | AE4: World, Equity Indices, MSCI, Mid & Large Cap, Index, Price Return, USD | AF4: United States, Policy Rates, Federal Reserve, Target Rates, Federal Funds Target Rate | AG4: Euro Area, Policy Rates, ECB, Deposit Facility, Effective Rate | AH4: United Kingdom, Policy Rates, Bank of England, Bank Rate | AI4: Japan, Policy Rates, Bank of Japan, Interest on Excess Reserves (Policy-Rate Balances in Current Accounts Held by Financial Institutions at the Bank) | AJ4: China, Liquidity Facilities, People's Bank of China, Medium-term Lending Facility, Medium-term Lending Facility, 1-Year Rate | AK4: United States, Consumer Price Index, Harmonized CPI (HICP), All Items, Index | AL4: United States, Consumer Price Index, All Urban Consumers, U.S. City Average, All Items Less Food & Energy, SA, Index | AM4: Germany, Business Surveys, S&P Global, Composite, Composite PMI Output Index, SA, Index | AN4: Germany, Business Surveys, S&P Global, Manufacturing, Manufacturing PMI, SA, Index | AO4: France, Business Surveys, S&P Global, Composite, Composite PMI Output Index, SA, Index | AP4: France, Business Surveys, S&P Global, Manufacturing, Manufacturing PMI, SA, Index | AQ4: United States, Business Surveys, S&P Global, Composite, Composite PMI Output Index, SA, Index | AR4: United States, Business Surveys, S&P Global, Manufacturing, Manufacturing PMI, SA, Index | AS4: United Kingdom, Business Surveys, S&P Global, Composite, Composite PMI Output Index, SA, Index | AT4: United Kingdom, Business Surveys, S&P Global, Manufacturing, Manufacturing PMI, SA, Index | AU4: China, Business Surveys, S&P Global, Composite, Caixin, Composite PMI Output Index, SA, Index | AV4: China, Business Surveys, S&P Global, Manufacturing, Caixin, Manufacturing PMI, SA, Index | AW4: India, Business Surveys, S&P Global, Composite, HSBC, Composite PMI Output Index, SA, Index | AX4: India, Business Surveys, S&P Global, Manufacturing, HSBC, Manufacturing PMI, SA, Index | AY4: World, Business Surveys, S&P Global, Composite, JPMorgan, Composite PMI Output Index, SA, Index | AZ4: World, Business Surveys, S&P Global, Manufacturing, JPMorgan, Manufacturing PMI, SA, Index | BA4: Japan, Business Surveys, S&P Global, Composite, au Jibun Bank, Composite PMI Output Index, SA, Index | BB4: Japan, Business Surveys, S&P Global, Manufacturing, au Jibun Bank, Manufacturing PMI, SA, Index | BC4: World, Foreign Trade, Global Supply Chain Pressure Index, Total, Index | BD4: World, Foreign Trade, CPB World Trade Monitor, Total, Volume, SA, Index | BE4: World, Foreign Trade, RWI/ISL Container Throughput Index, Total, SA, Index | BF4: World, Foreign Trade, RWI/ISL Container Throughput Index, North Range, SA, Index | BG4: United States, Corporate Benchmarks, Moody's, Long-Term, Baa Rated, Yield | BH4: United States, Economic Policy Uncertainty, Trade Policy Uncertainty (TPU), Trade Policy Uncertainty Index (TPU), Index | BI4: Euro Area 20, ECB, Hourly Compensation, Total - All Activities, Reference Sector: Total Economy, Counterpart Area: Domestic (Home or Reference Area), Calendar Adjusted, Current Prices, SA, Index | BJ4: Euro Area 20, Eurostat, Labor Cost Index - Nominal Value, Labor Cost, Wages & Salaries (Total), Industry, Construction & Services (Except Activities of Households as Employers & Extra-Territorial Organisations & Bodies) (B-S), 2020=100, Calendar Adjusted, SA, Index | BK4: Natural Gas, Future, ICE Dutch TTF Daily Gas, 1st Position, Close, EUR | BL4: Netherlands, Business Surveys, S&P Global, Manufacturing, Manufacturing PMI, SA, Index | BM4: Euro Area, Interbank Rates, EURIBOR, 3 Month, Fixing | BN4: Netherlands, Government Benchmarks, Macrobond, 10 Year, Yield | BO4: United States, OECD MEI, Leading Indicators OECD, Leading Indicators, Composite Leading Indicators, Amplitude Adjusted, OECD, SA, Index | BP4: China, OECD MEI, Leading Indicators OECD, Leading Indicators, Composite Leading Indicators, Amplitude Adjusted, OECD, SA, Index | BQ4: Four Big European, OECD MEI, Leading Indicators OECD, Leading Indicators, Composite Leading Indicators, Amplitude Adjusted, OECD, SA, Index | BR4: Euro Area, Commodity Indices, HWWI, Weighting Period 2017-2019, HWWI Index, Average of Period, EUR | BS4: Euro Area, Commodity Indices, HWWI, Weighting Period 2017-2019, HWWI Index excluding Energy, Average of Period, EUR | BT4: Euro Area, Commodity Indices, HWWI, Weighting Period 2017-2019, Industrial Raw Materials Index, Average of Period, EUR | BU4: Euro Area, Commodity Indices, HWWI, Weighting Period 2017-2019, Energy Raw Materials Index, Average of Period, EUR | BV4: Euro Area, Commodity Indices, HWWI, Weighting Period 2017-2019, Food Index, Average of Period, EUR | BW4: World, Foreign Trade, Kiel Institute, Export, Real Trade Flows, SA, Change P/P | BX4: World, Foreign Trade, Kiel Institute, Import, Real Trade Flows, SA, Change P/P | BY4: Euro Area 20, Foreign Trade, Kiel Institute, Import, Real Trade Flows, Extra-Euro Area 20, SA, Change P/P | BZ4: Euro Area 20, Foreign Trade, Kiel Institute, Export, Real Trade Flows, Extra-Euro Area 20, SA, Change P/P | CA4: Euro Area 20, Foreign Trade, Kiel Institute, Import, Real Trade Flows, Intra-Euro Area 20, SA, Change P/P | CB4: Euro Area 20, Foreign Trade, Kiel Institute, Export, Real Trade Flows, Intra-Euro Area 20, SA, Change P/P | CC4: Netherlands, ECB Composite Cost of Borrowing, For Non-Financial Corporations | CD4: Netherlands, ECB Composite Cost of Borrowing, For Short-Term Loans | CE4: Netherlands, ECB Composite Cost of Borrowing, For Long-Term Loans | CF4: Netherlands, ECB Composite Cost of Borrowing, For Households For House Purchase | CG4: Netherlands, Business Surveys, DG ECFIN, Services Confidence Indicator, Total Service Sector, Balance, SA | CH4: Netherlands, Business Surveys, DG ECFIN, Industrial Confidence Indicator, Total Sector, Monthly, Balance, SA | CI4: Netherlands, Business Surveys, DG ECFIN, Construction Confidence Indicator, Balance, SA | CJ4: Netherlands, Business Surveys, DG ECFIN, Retail Trade Confidence Indicator, Balance, SA
A5: 30317 | C5: 1.0662 | G5: 7.71 | H5: 10.8 | AD5: 145.3 | AE5: 158.0337 | AF5: 8.5 | AH5: 11 | AL5: 97.6 | BG5: 14.11 | BH5: 44.216434 | BO5: 98.59094 | BQ5: 98.85226
A6: 30348 | C6: 1.0593 | G6: 7.71 | H6: 10.27 | AD6: 148.06 | AE6: 160.9138 | AF6: 8.5 | AH6: 11 | AL6: 98 | BG6: 14.11 | BH6: 47.943553 | BO6: 99.20538 | BQ6: 99.03355
A7: 30376 | C7: 1.0825 | G7: 7.42 | H7: 10.62 | AD7: 152.96 | AE7: 166.1387 | AF7: 8.625 | AH7: 10.5625 | AL7: 98.2 | BG7: 14.11 | BH7: 39.36063 | BO7: 99.83798 | BQ7: 99.21072
A8: 30407 | C8: 1.0857 | G8: 7.51 | H8: 10.27 | AD8: 164.42 | AE8: 177.5606 | AF8: 8.625 | AH8: 10.0625 | AL8: 98.6 | BG8: 14.11 | BH8: 33.669141 | BO8: 100.4557 | BQ8: 99.36791
A9: 30437 | C9: 1.1038 | G9: 7.69 | H9: 10.81 | AD9: 162.39 | AE9: 175.3825 | AF9: 8.75 | AH9: 10.0625 | AL9: 98.9 | BG9: 14.11 | BH9: 40.559676 | BO9: 101.0241 | BQ9: 99.51093
A10: 30468 | C10: 1.1214 | G10: 8.11 | H10: 10.96 | AD10: 168.11 | AE10: 180.4522 | AF10: 9 | AH10: 9.5625 | AL10: 99.2 | BG10: 14.11 | BH10: 30.909182 | BO10: 101.5105 | BQ10: 99.65131
A11: 30498 | C11: 1.1599 | G11: 8.24 | H11: 11.76 | AD11: 162.56 | AE11: 176.796 | AF11: 9.4375 | AH11: 9.5625 | AL11: 99.8 | BG11: 14.11 | BH11: 38.485725 | BO11: 101.8985 | BQ11: 99.78407
A12: 30529 | C12: 1.1868 | G12: 8.37 | H12: 11.98 | AD12: 164.4 | AE12: 177.3121 | AF12: 9.5 | AH12: 9.5625 | AL12: 100.1 | BG12: 14.11 | BH12: 27.837468 | BO12: 102.1883 | BQ12: 99.90173
A13: 30560 | C13: 1.1636 | G13: 8.48 | H13: 11.44 | AD13: 166.07 | AE13: 180.4669 | AF13: 9.375 | AH13: 9.5625 | AL13: 100.5 | BG13: 14.11 | BH13: 29.90736 | BO13: 102.4 | BQ13: 99.99452
A14: 30590 | C14: 1.1641 | G14: 8.26 | H14: 11.74 | AD14: 163.55 | AE14: 177.9077 | AF14: 9.375 | AH14: 9.0625 | AL14: 101 | BG14: 14.11 | BH14: 26.994876 | BO14: 102.5413 | BQ14: 100.0811
A15: 30621 | C15: 1.1928 | G15: 8.31 | H15: 11.63 | AD15: 166.4 | AE15: 182.0605 | AF15: 9.375 | AH15: 9.0625 | AL15: 101.5 | BG15: 14.11 | BH15: 30.371025 | BO15: 102.6177 | BQ15: 100.1606
A16: 30651 | C16: 1.2086 | G16: 8.41 | H16: 11.82 | AD16: 164.93 | AE16: 183.952 | AF16: 9.375 | AH16: 9.0625 | AL16: 101.8 | BG16: 14.11 | BH16: 24.386279 | BO16: 102.6312 | BQ16: 100.215
... A28: 31017 | C28: 1.4105 | G28: 7.04 | H28: 11.55 | AD28: 167.24 | AE28: 187.205 | AF28: 8.125 | AH28: 9.5 | AL28: 106.8 | BG28: 14.11 | BH28: 25.772489 | BO28: 100.3601 | BQ28: 99.74073
A29: 31048 | C29: 1.4226 | D29: 125.22474 | G29: 7.12 | H29: 11.17 | U29: -10.4 | V29: -0.18 | X29: -5.9 | Y29: -50.1 | AD29: 179.63 | AE29: 197.0574 | AF29: 8.25 | AH29: 13.875 | AL29: 107.1 | BG29: 14.11 | BH29: 26.59244 | BO29: 100.3054 | BQ29: 99.71529 | CH29: -3.2 | CI29: -23.1
A30: 31079 | C30: 1.4978 | D30: 99.020809 | G30: 7.59 | H30: 11.91 | U30: -10.8 | V30: -0.18 | X30: -8 | Y30: -51.1 | Z30: 984 | AD30: 181.19 | AE30: 196.9641 | AF30: 8.375 | AH30: 13.875 | AL30: 107.7 | BG30: 14.11 | BH30: 30.645161 | BO30: 100.2539 | BQ30: 99.67143 | CH30: 1.8 | CI30: -18.4
A31: 31107 | C31: 1.3753 | D31: 112.19051 | G31: 7.63 | H31: 11.65 | U31: -11.8 | V31: -0.27 | X31: -9.5 | Y31: -48.3 | Z31: 1016 | AD31: 180.66 | AE31: 203.3034 | AF31: 8.5 | AH31: 12.875 | AL31: 108.1 | BG31: 14.11 | BH31: 42.439081 | BO31: 100.2115 | BQ31: 99.62137 | CH31: 1.9 | CI31: -20.6
A32: 31138 | C32: 1.3807 | D32: 102.81132 | G32: 7.31 | H32: 11.41 | U32: -11 | V32: -0.24 | X32: -8.8 | Y32: -45.1 | Z32: 1063 | AD32: 179.83 | AE32: 202.2416 | AF32: 8.25 | AH32: 12.375 | AL32: 108.4 | BG32: 14.11 | BH32: 42.02379 | BO32: 100.1772 | BQ32: 99.57984 | CH32: -1.3 | CI32: -20.1
A33: 31168 | C33: 1.3764 | D33: 120.08272 | G33: 7.2 | H33: 10.28 | U33: -11.5 | V33: -0.11 | X33: -7.6 | Y33: -45.2 | Z33: 932 | AD33: 189.57 | AE33: 212.126 | AF33: 7.75 | AH33: 12.375 | AL33: 108.8 | BG33: 14.11 | BH33: 31.659582 | BO33: 100.1469 | BQ33: 99.54821 | CH33: -1.5 | CI33: -23.9
A34: 31199 | C34: 1.3606 | D34: 132.71319 | G34: 7.05 | H34: 10.25 | U34: -11.9 | V34: -0.14 | X34: -7.9 | Y34: -43.3 | Z34: 872 | AD34: 191.85 | AE34: 215.3965 | AF34: 7.75 | AH34: 12.375 | AL34: 109.1 | BG34: 14.11 | BH34: 34.803326 | BO34: 100.121 | BQ34: 99.52658 | CH34: -1 | CI34: -22.7
A35: 31229 | C35: 1.2477 | D35: 128.00182 | G35: 6.86 | H35: 10.57 | U35: -11.6 | V35: -0.1 | X35: -8.1 | Y35: -40.9 | Z35: 726 | AD35: 190.92 | AE35: 219.314 | AF35: 7.75 | AH35: 11.375 | AL35: 109.4 | BG35: 14.11 | BH35: 50.395429 | BO35: 100.0893 | BQ35: 99.52212 | CH35: 0 | CI35: -20.7
A36: 31260 | C36: 1.2494 | D36: 126.76611 | G36: 6.59 | H36: 10.28 | U36: -11.2 | V36: -0.1 | X36: -7.6 | Y36: -38.8 | Z36: 738 | AD36: 188.63 | AE36: 220.5866 | AF36: 7.8125 | AH36: 11.375 | AL36: 109.8 | BG36: 14.11 | BH36: 41.984177 | BO36: 100.061 | BQ36: 99.54453 | CH36: -2.7 | CI36: -19.8
A37: 31291 | C37: 1.2103 | D37: 126.76856 | G37: 6.4 | H37: 10.31 | U37: -10.9 | V37: -0.1 | X37: -6.3 | Y37: -35.7 | Z37: 894 | AD37: 182.08 | AE37: 221.7017 | AF37: 8 | AH37: 11.375 | AL37: 110 | BG37: 14.11 | BH37: 60.030251 | BO37: 100.0409 | BQ37: 99.59404 | CH37: -3.2 | CI37: -17.4
A38: 31321 | C38: 1.1824 | D38: 116.05771 | G38: 6.59 | H38: 10.01 | U38: -8.3 | V38: -0.01 | X38: -5.8 | Y38: -34.8 | Z38: 905 | AD38: 189.82 | AE38: 233.095 | AF38: 8 | AH38: 11.375 | AL38: 110.5 | BG38: 14.11 | BH38: 36.138472 | BO38: 100.0354 | BQ38: 99.66045 | CH38: -2.8 | CI38: -14.6
A39: 31352 | C39: 1.1401 | D39: 122.03688 | G39: 6.58 | H39: 9.59 | U39: -8 | V39: -0.11 | X39: -5.2 | Y39: -34.4 | Z39: 915 | AD39: 202.17 | AE39: 245.5733 | AF39: 8 | AH39: 11.375 | AL39: 111.1 | BG39: 14.11 | BH39: 39.581438 | BO39: 100.0505 | BQ39: 99.72504 | CH39: -2.5 | CI39: -15.2
A40: 31382 | C40: 1.1262 | D40: 133.24392 | G40: 6.45 | H40: 9 | U40: -8.2 | V40: -0.16 | X40: -6.6 | Y40: -35.3 | Z40: 898 | AD40: 211.28 | AE40: 256.5141 | AF40: 7.75 | AH40: 11.375 | AL40: 111.4 | BG40: 14.11 | BH40: 44.467208 | BO40: 100.0822 | BQ40: 99.78174 | CH40: -4 | CI40: -7.5
A41: 31413 | C41: 1.1022 | D41: 155.93292 | G41: 6.31 | H41: 9.08 | U41: -5.7 | V41: -0.23 | X41: -7.3 | Y41: -34.6 | Z41: 831 | AC41: 119.53 | AD41: 211.78 | AE41: 259.7475 | AF41: 7.75 | AH41: 12.375 | AL41: 111.9 | BG41: 11.37 | BH41: 40.251376 | BO41: 100.1082 | BQ41: 99.83704 | CH41: -1.1 | CI41: -9.2 | CJ41: 31.1
A42: 31444 | C42: 1.0425 | D42: 159.46768 | G42: 6.23 | H42: 8.13 | U42: -5 | V42: -0.21 | X42: -6.9 | Y42: -35.9 | Z42: 737 | AC42: 112.4 | AD42: 226.92 | AE42: 282.5747 | AF42: 7.75 | AH42: 12.375 | AL42: 112.2 | BG42: 10.62 | BH42: 41.183392 | BO42: 100.1166 | BQ42: 99.89671 | CH42: -3.8 | CI42: -7.9 | CJ42: 28.5
A43: 31472 | C43: 1.0652 | D43: 160.1981 | G43: 5.75 | H43: 7.39 | U43: -4.5 | V43: -0.19 | X43: -6.8 | Y43: -33.5 | Z43: 734 | AC43: 122.43 | AD43: 238.9 | AE43: 309.6008 | AF43: 7.25 | AH43: 11.375 | AL43: 112.5 | BG43: 10.31 | BH43: 40.270821 | BO43: 100.1083 | BQ43: 99.95715 | CH43: -4.3 | CI43: -1.2 | CJ43: 29.1
A44: 31503 | C44: 1.0103 | D44: 150.36626 | G44: 5.36 | H44: 7.38 | U44: -5 | V44: -0.27 | X44: -7.3 | Y44: -30.7 | Z44: 658 | AC44: 120.12 | AD44: 235.52 | AE44: 317.5024 | AF44: 6.75 | AH44: 10.375 | AL44: 112.9 | BG44: 10.16 | BH44: 43.61628 | BO44: 100.0924 | BQ44: 100.0071 | CH44: -4.9 | CI44: 5.8 | CJ44: 29.6
A45: 31533 | C45: 1.0747 | D45: 132.63792 | G45: 5.75 | H45: 8.05 | J45: 6.34 | U45: -5.4 | V45: -0.21 | X45: -6.8 | Y45: -28.9 | Z45: 665 | AC45: 126.14 | AD45: 247.35 | AE45: 315.9833 | AF45: 6.8125 | AH45: 9.785 | AL45: 113.1 | BG45: 10.41 | BH45: 41.71588 | BN45: 6.34 | BO45: 100.0741 | BQ45: 100.0301 | CH45: -4.7 | CI45: 4.9 | CJ45: 31.4
A46: 31564 | C46: 1.0215 | D46: 122.51177 | G46: 5.87 | H46: 7.35 | J46: 6.24 | U46: -5.4 | V46: -0.26 | X46: -6.9 | Y46: -28.2 | Z46: 586 | AC46: 123.63 | AD46: 250.84 | AE46: 328.0407 | AF46: 6.875 | AH46: 9.785 | AL46: 113.4 | BG46: 10.16 | BH46: 41.210594 | BN46: 6.24 | BO46: 100.042 | BQ46: 100.0373 | CH46: -4.6 | CI46: 4.6 | CJ46: 31.1
A47: 31594 | C47: 0.9923 | D47: 132.11963 | G47: 5.77 | H47: 7.34 | J47: 6.16 | U47: -5.4 | V47: -0.27 | X47: -6.8 | Y47: -26.4 | Z47: 554 | AC47: 119.01 | AD47: 236.12 | AE47: 330.052 | AF47: 6.375 | AH47: 9.785 | AL47: 113.8 | BG47: 10.25 | BH47: 32.038759 | BN47: 6.16 | BO47: 99.99278 | BQ47: 100.0309 | CH47: -3.7 | CI47: -6.2 | CJ47: 29
A48: 31625 | C48: 0.9711 | D48: 127.5525 | G48: 5.6 | H48: 6.95 | J48: 5.89 | U48: -4.4 | V48: -0.3 | X48: -6.5 | Y48: -24.8 | Z48: 664 | AC48: 120.43 | AD48: 252.93 | AE48: 358.2604 | AF48: 5.875 | AH48: 9.785 | AL48: 114.2 | BG48: 10.02 | BH48: 37.768814 | BN48: 5.89 | BO48: 99.94153 | BQ48: 100.0136 | CH48: -5.6 | CI48: -3.3 | CJ48: 31.7
A49: 31656 | C49: 0.9699 | D49: 132.01833 | G49: 5.82 | H49: 7.45 | J49: 6.08 | U49: -4.4 | V49: -0.33 | X49: -7.2 | Y49: -23.7 | Z49: 800 | AC49: 115.25 | AD49: 231.32 | AE49: 343.3508 | AF49: 5.875 | AH49: 9.785 | AL49: 114.6 | BG49: 10.2 | BH49: 49.158038 | BN49: 6.08 | BO49: 99.89735 | BQ49: 99.98862 | CH49: -6.4 | CI49: -5.6 | CJ49: 32.3
A50: 31686 | C50: 0.9906 | D50: 111.50926 | G50: 6.14 | H50: 7.34 | J50: 6.24 | U50: -4 | V50: -0.41 | X50: -8.3 | Y50: -23.9 | Z50: 786 | AC50: 116.06 | AD50: 243.98 | AE50: 336.8208 | AF50: 5.875 | AH50: 10.875 | AL50: 115 | BG50: 10.16 | BH50: 43.373721 | BN50: 6.24 | BO50: 99.8709 | BQ50: 99.96295 | CH50: -4.9 | CI50: -6.7 | CJ50: 29.6
A51: 31717 | C51: 0.9504 | D51: 115.02029 | G51: 6.17 | H51: 7.15 | J51: 6.16 | U51: -4.3 | V51: -0.43 | X51: -7.7 | Y51: -25.1 | Z51: 738 | AC51: 118.99 | AD51: 249.22 | AE51: 350.4577 | AF51: 5.875 | AH51: 10.875 | AL51: 115.3 | BG51: 10 | BH51: 44.255445 | BN51: 6.16 | BO51: 99.88484 | BQ51: 99.94996 | CH51: -4.7 | CI51: -10.7 | CJ51: 29.3
A52: 31747 | C52: 0.9271 | D52: 108.96811 | G52: 5.96 | H52: 7.23 | J52: 6.27 | U52: -4.7 | V52: -0.34 | X52: -6.9 | Y52: -26.5 | Z52: 699 | AC52: 114.69 | AD52: 242.16 | AE52: 356.8254 | AF52: 5.875 | AH52: 10.875 | AL52: 115.6 | BG52: 9.99 | BH52: 33.568141 | BN52: 6.27 | BO52: 99.96575 | BQ52: 99.97139 | CH52: -4.5 | CI52: -6.4 | CJ52: 33.2
A53: 31778 | C53: 0.8899 | D53: 122.11428 | E53: 57.107346 | G53: 5.95 | H53: 7.18 | J53: 6.08 | U53: -4.7 | V53: -0.39 | X53: -8 | Y53: -28.4 | Z53: 866 | AC53: 106.75 | AD53: 274.08 | AE53: 398.1059 | AF53: 6 | AH53: 10.875 | AL53: 115.9 | BG53: 9.68 | BH53: 51.199847 | BN53: 6.08 | BO53: 100.1237 | BQ53: 100.0465 | CH53: -6.2 | CI53: -6.9 | CJ53: 26.8
A54: 31809 | C54: 0.8842 | D54: 109.14523 | E54: 49.240593 | G54: 5.94 | H54: 7.19 | J54: 6.21 | U54: -5.4 | V54: -0.54 | X54: -9.1 | Y54: -28.1 | Z54: 852 | AC54: 106.16 | AD54: 284.2 | AE54: 410.5891 | AF54: 6 | AH54: 10.875 | AL54: 116.2 | BG54: 9.62 | BH54: 48.559818 | BN54: 6.21 | BO54: 100.3355 | BQ54: 100.148 | CH54: -4.5 | CI54: -1.7 | CJ54: 29
...

Sheet maandcijfers
B1: oliepr | C1: dollar | D1: Beleidsonzekerheid VS | E1: Beleidsonzekerheid EU | F1: Volatiliteit US S&P500 | G1: lange rente Duitsland | H1: lange rente VS | I1: lange rente Italie | J1: lange rente Nederland | K1: HICP eurogebied, totaal | L1: HICP eurogebied, voeding, alc. en tabak | M1: HICP eurogebied, energie | N1: HICP eurogebied, totaal, excl. energie, voeding en tabak | O1: import volume eurogebied (WTM) | P1: export volume eurogebied (WTM) | Q1: PMI samengesteld eurozone | R1: PMI industrie eurozone | S1: PMI diensten eurozone | T1: PMI bouw eurozone | U1: consumentenvertrouwen eurozone | V1: ondernemersvertrouwen eurozone | W1: dienstensector vertrouwenindicator eurozone | X1: industrie vertrouwenindicator eurozone | Y1: bouwsector vertrouwenindicator eurozone | Z1: Baltic Dry Index | AA1: Harpex index | AB1: Global Container Freight Index | AC1: beurs_aex | AD1: SP_500 | AE1: MSCI World | AF1: US Federal funds rate | AG1: ECB Deposit rate | AH1: United Kingdom Bank Rate | AI1: Japan key policy rate | AJ1: PBOC Medium-term Lending Facility | AK1: CPI Verenigde Staten | AL1: CPI excl voedsel en energie VS | AM1: PMI samengesteld Duitsland | AN1: PMI industrie Duitsland | AO1: PMI samengesteld Frankrijk | AP1: PMI industrie Frankrijk | AQ1: PMI samengesteld VS | AR1: PMI industrie VS | AS1: PMI samengesteld VK | AT1: PMI industrie VK | AU1: PMI samengesteld China | AV1: PMI industrie China | AW1: PMI samengesteld India | AX1: PMI industrie India | AY1: PMI samengesteld Wereld | AZ1: PMI industrie Wereld | BA1: PMI samengesteld Japan | BB1: PMI industrie Japan | BC1: Global Supply chain pressure index | BD1: Wereldhandel (WTM) | BE1: Container throughput - Wereld | BF1: Container throughput - Noordwest-Europa | BG1: US Corporate Long-term bond yield | BH1: Trade Policy Uncertainty | BI1: Looncompensatie per uur - eurozone | BJ1: Loonkosten index (op uurbasis)- eurozone | BK1: Gas futures | BL1: PMI industrie - Nederland | BM1: EURIBOR | BN1: interest NL 10yr | BO1: CLI - VS | BP1: CLI - CHN | BQ1: CLI -EU | BR1: HWWI index | BS1: HWWI excl Energy index | BT1: HWWI Industrial Raw Materials index | BU1: HWWI Energy raw materials | BV1: HWWI Food index | BW1: Wereld uitvoer | BX1: Wereld Invoer | BY1: Eurozone extra-EA20 invoer | BZ1: Eurozone extra-EA20 uitvoer | CA1: Eurozone intra-EA20 invoer | CB1: Eurozone intra-EA20 uitvoer | CC1: NL - leenkosten NFC's | CD1: NL- leenkosten KT | CE1: NL- leenkosten LT | CF1: NL - Hypotheekrente
A2: 30317 | B2: =IF(Downloads_maandcijfers!B5="", "", Downloads_maandcijfers!B5) | C2: =IF(Downloads_maandcijfers!C5="", "", Downloads_maandcijfers!C5) -> 1.0662 | D2: =IF(Downloads_maandcijfers!D5="", "", Downloads_maandcijfers!D5) | E2: =IF(Downloads_maandcijfers!E5="", "", Downloads_maandcijfers!E5) | F2: =IF(Downloads_maandcijfers!F5="", "", Downloads_maandcijfers!F5) | G2: =IF(Downloads_maandcijfers!G5="", "", Downloads_maandcijfers!G5) -> 7.71 | H2: =IF(Downloads_maandcijfers!H5="", "", Downloads_maandcijfers!H5) -> 10.8 | I2: =IF(Downloads_maandcijfers!I5="", "", Downloads_maandcijfers!I5) | ... AB2: =IF(Downloads_maandcijfers!AB5="", "", Downloads_maandcijfers!AB5) | AC2: 48.37 | AD2: =IF(Downloads_maandcijfers!AD5="", "", Downloads_maandcijfers!AD5) -> 145.3 | AE2: =IF(Downloads_maandcijfers!AE5="", "", Downloads_maandcijfers!AE5) -> 158.0337 | AF2: =IF(Downloads_maandcijfers!AF5="", "", Downloads_maandcijfers!AF5) -> 8.5 | AG2: =IF(Downloads_maandcijfers!AG5="", "", Downloads_maandcijfers!AG5) | AH2: =IF(Downloads_maandcijfers!AH5="", "", Downloads_maandcijfers!AH5) -> 11 | AI2: =IF(Downloads_maandcijfers!AI5="", "", Downloads_maandcijfers!AI5) | AJ2: =IF(Downloads_maandcijfers!AJ5="", "", Downloads_maandcijfers!AJ5) | AK2: =IF(Downloads_maandcijfers!AK5="", "", Downloads_maandcijfers!AK5) | ... CF2: =IF(Downloads_maandcijfers!CF5="", "", Downloads_maandcijfers!CF5)
A3: 30348 | B3: =IF(Downloads_maandcijfers!B6="", "", Downloads_maandcijfers!B6) | C3: =IF(Downloads_maandcijfers!C6="", "", Downloads_maandcijfers!C6) -> 1.0593 | D3: =IF(Downloads_maandcijfers!D6="", "", Downloads_maandcijfers!D6) | E3: =IF(Downloads_maandcijfers!E6="", "", Downloads_maandcijfers!E6) | F3: =IF(Downloads_maandcijfers!F6="", "", Downloads_maandcijfers!F6) | G3: =IF(Downloads_maandcijfers!G6="", "", Downloads_maandcijfers!G6) -> 7.71 | H3: =IF(Downloads_maandcijfers!H6="", "", Downloads_maandcijfers!H6) -> 10.27 | I3: =IF(Downloads_maandcijfers!I6="", "", Downloads_maandcijfers!I6) | ... AB3: =IF(Downloads_maandcijfers!AB6="", "", Downloads_maandcijfers!AB6) | AC3: 51.26 | AD3: =IF(Downloads_maandcijfers!AD6="", "", Downloads_maandcijfers!AD6) -> 148.06 | AE3: =IF(Downloads_maandcijfers!AE6="", "", Downloads_maandcijfers!AE6) -> 160.9138 | AF3: =IF(Downloads_maandcijfers!AF6="", "", Downloads_maandcijfers!AF6) -> 8.5 | AG3: =IF(Downloads_maandcijfers!AG6="", "", Downloads_maandcijfers!AG6) | AH3: =IF(Downloads_maandcijfers!AH6="", "", Downloads_maandcijfers!AH6) -> 11 | AI3: =IF(Downloads_maandcijfers!AI6="", "", Downloads_maandcijfers!AI6) | AJ3: =IF(Downloads_maandcijfers!AJ6="", "", Downloads_maandcijfers!AJ6) | AK3: =IF(Downloads_maandcijfers!AK6="", "", Downloads_maandcijfers!AK6) | ... CF3: =IF(Downloads_maandcijfers!CF6="", "", Downloads_maandcijfers!CF6)
A4: 30376 | B4: =IF(Downloads_maandcijfers!B7="", "", Downloads_maandcijfers!B7) | C4: =IF(Downloads_maandcijfers!C7="", "", Downloads_maandcijfers!C7) -> 1.0825 | D4: =IF(Downloads_maandcijfers!D7="", "", Downloads_maandcijfers!D7) | E4: =IF(Downloads_maandcijfers!E7="", "", Downloads_maandcijfers!E7) | F4: =IF(Downloads_maandcijfers!F7="", "", Downloads_maandcijfers!F7) | G4: =IF(Downloads_maandcijfers!G7="", "", Downloads_maandcijfers!G7) -> 7.42 | H4: =IF(Downloads_maandcijfers!H7="", "", Downloads_maandcijfers!H7) -> 10.62 | I4: =IF(Downloads_maandcijfers!I7="", "", Downloads_maandcijfers!I7) | ... AB4: =IF(Downloads_maandcijfers!AB7="", "", Downloads_maandcijfers!AB7) | AC4: 60.24 | AD4: =IF(Downloads_maandcijfers!AD7="", "", Downloads_maandcijfers!AD7) -> 152.96 | AE4: =IF(Downloads_maandcijfers!AE7="", "", Downloads_maandcijfers!AE7) -> 166.1387 | AF4: =IF(Downloads_maandcijfers!AF7="", "", Downloads_maandcijfers!AF7) -> 8.625 | AG4: =IF(Downloads_maandcijfers!AG7="", "", Downloads_maandcijfers!AG7) | AH4: =IF(Downloads_maandcijfers!AH7="", "", Downloads_maandcijfers!AH7) -> 10.5625 | AI4: =IF(Downloads_maandcijfers!AI7="", "", Downloads_maandcijfers!AI7) | AJ4: =IF(Downloads_maandcijfers!AJ7="", "", Downloads_maandcijfers!AJ7) | AK4: =IF(Downloads_maandcijfers!AK7="", "", Downloads_maandcijfers!AK7) | ... CF4: =IF(Downloads_maandcijfers!CF7="", "", Downloads_maandcijfers!CF7)
A5: 30407 | B5: =IF(Downloads_maandcijfers!B8="", "", Downloads_maandcijfers!B8) | C5: =IF(Downloads_maandcijfers!C8="", "", Downloads_maandcijfers!C8) -> 1.0857 | D5: =IF(Downloads_maandcijfers!D8="", "", Downloads_maandcijfers!D8) | E5: =IF(Downloads_maandcijfers!E8="", "", Downloads_maandcijfers!E8) | F5: =IF(Downloads_maandcijfers!F8="", "", Downloads_maandcijfers!F8) | G5: =IF(Downloads_maandcijfers!G8="", "", Downloads_maandcijfers!G8) -> 7.51 | H5: =IF(Downloads_maandcijfers!H8="", "", Downloads_maandcijfers!H8) -> 10.27 | I5: =IF(Downloads_maandcijfers!I8="", "", Downloads_maandcijfers!I8) | ... AB5: =IF(Downloads_maandcijfers!AB8="", "", Downloads_maandcijfers!AB8) | AC5: 57.2 | AD5: =IF(Downloads_maandcijfers!AD8="", "", Downloads_maandcijfers!AD8) -> 164.42 | AE5: =IF(Downloads_maandcijfers!AE8="", "", Downloads_maandcijfers!AE8) -> 177.5606 | AF5: =IF(Downloads_maandcijfers!AF8="", "", Downloads_maandcijfers!AF8) -> 8.625 | AG5: =IF(Downloads_maandcijfers!AG8="", "", Downloads_maandcijfers!AG8) | AH5: =IF(Downloads_maandcijfers!AH8="", "", Downloads_maandcijfers!AH8) -> 10.0625 | AI5: =IF(Downloads_maandcijfers!AI8="", "", Downloads_maandcijfers!AI8) | AJ5: =IF(Downloads_maandcijfers!AJ8="", "", Downloads_maandcijfers!AJ8) | AK5: =IF(Downloads_maandcijfers!AK8="", "", Downloads_maandcijfers!AK8) | ... CF5: =IF(Downloads_maandcijfers!CF8="", "", Downloads_maandcijfers!CF8)
A6: 30437 | B6: =IF(Downloads_maandcijfers!B9="", "", Downloads_maandcijfers!B9) | C6: =IF(Downloads_maandcijfers!C9="", "", Downloads_maandcijfers!C9) -> 1.1038 | D6: =IF(Downloads_maandcijfers!D9="", "", Downloads_maandcijfers!D9) | E6: =IF(Downloads_maandcijfers!E9="", "", Downloads_maandcijfers!E9) | F6: =IF(Downloads_maandcijfers!F9="", "", Downloads_maandcijfers!F9) | G6: =IF(Downloads_maandcijfers!G9="", "", Downloads_maandcijfers!G9) -> 7.69 | H6: =IF(Downloads_maandcijfers!H9="", "", Downloads_maandcijfers!H9) -> 10.81 | I6: =IF(Downloads_maandcijfers!I9="", "", Downloads_maandcijfers!I9) | ... AB6: =IF(Downloads_maandcijfers!AB9="", "", Downloads_maandcijfers!AB9) | AC6: 57.24 | AD6: =IF(Downloads_maandcijfers!AD9="", "", Downloads_maandcijfers!AD9) -> 162.39 | AE6: =IF(Downloads_maandcijfers!AE9="", "", Downloads_maandcijfers!AE9) -> 175.3825 | AF6: =IF(Downloads_maandcijfers!AF9="", "", Downloads_maandcijfers!AF9) -> 8.75 | AG6: =IF(Downloads_maandcijfers!AG9="", "", Downloads_maandcijfers!AG9) | AH6: =IF(Downloads_maandcijfers!AH9="", "", Downloads_maandcijfers!AH9) -> 10.0625 | AI6: =IF(Downloads_maandcijfers!AI9="", "", Downloads_maandcijfers!AI9) | AJ6: =IF(Downloads_maandcijfers!AJ9="", "", Downloads_maandcijfers!AJ9) | AK6: =IF(Downloads_maandcijfers!AK9="", "", Downloads_maandcijfers!AK9) | ... CF6: =IF(Downloads_maandcijfers!CF9="", "", Downloads_maandcijfers!CF9)
A7: 30468 | B7: =IF(Downloads_maandcijfers!B10="", "", Downloads_maandcijfers!B10) | C7: =IF(Downloads_maandcijfers!C10="", "", Downloads_maandcijfers!C10) -> 1.1214 | D7: =IF(Downloads_maandcijfers!D10="", "", Downloads_maandcijfers!D10) | E7: =IF(Downloads_maandcijfers!E10="", "", Downloads_maandcijfers!E10) | F7: =IF(Downloads_maandcijfers!F10="", "", Downloads_maandcijfers!F10) | G7: =IF(Downloads_maandcijfers!G10="", "", Downloads_maandcijfers!G10) -> 8.11 | H7: =IF(Downloads_maandcijfers!H10="", "", Downloads_maandcijfers!H10) -> 10.96 | I7: =IF(Downloads_maandcijfers!I10="", "", Downloads_maandcijfers!I10) | ... AB7: =IF(Downloads_maandcijfers!AB10="", "", Downloads_maandcijfers!AB10) | AC7: 64.01 | AD7: =IF(Downloads_maandcijfers!AD10="", "", Downloads_maandcijfers!AD10) -> 168.11 | AE7: =IF(Downloads_maandcijfers!AE10="", "", Downloads_maandcijfers!AE10) -> 180.4522 | AF7: =IF(Downloads_maandcijfers!AF10="", "", Downloads_maandcijfers!AF10) -> 9 | AG7: =IF(Downloads_maandcijfers!AG10="", "", Downloads_maandcijfers!AG10) | AH7: =IF(Downloads_maandcijfers!AH10="", "", Downloads_maandcijfers!AH10) -> 9.5625 | AI7: =IF(Downloads_maandcijfers!AI10="", "", Downloads_maandcijfers!AI10) | AJ7: =IF(Downloads_maandcijfers!AJ10="", "", Downloads_maandcijfers!AJ10) | AK7: =IF(Downloads_maandcijfers!AK10="", "", Downloads_maandcijfers!AK10) | ... CF7: =IF(Downloads_maandcijfers!CF10="", "", Downloads_maandcijfers!CF10)
A8: 30498 | B8: =IF(Downloads_maandcijfers!B11="", "", Downloads_maandcijfers!B11) | C8: =IF(Downloads_maandcijfers!C11="", "", Downloads_maandcijfers!C11) -> 1.1599 | D8: =IF(Downloads_maandcijfers!D11="", "", Downloads_maandcijfers!D11) | E8: =IF(Downloads_maandcijfers!E11="", "", Downloads_maandcijfers!E11) | F8: =IF(Downloads_maandcijfers!F11="", "", Downloads_maandcijfers!F11) | G8: =IF(Downloads_maandcijfers!G11="", "", Downloads_maandcijfers!G11) -> 8.24 | H8: =IF(Downloads_maandcijfers!H11="", "", Downloads_maandcijfers!H11) -> 11.76 | I8: =IF(Downloads_maandcijfers!I11="", "", Downloads_maandcijfers!I11) | ... AB8: =IF(Downloads_maandcijfers!AB11="", "", Downloads_maandcijfers!AB11) | AC8: 66.06 | AD8: =IF(Downloads_maandcijfers!AD11="", "", Downloads_maandcijfers!AD11) -> 162.56 | AE8: =IF(Downloads_maandcijfers!AE11="", "", Downloads_maandcijfers!AE11) -> 176.796 | AF8: =IF(Downloads_maandcijfers!AF11="", "", Downloads_maandcijfers!AF11) -> 9.4375 | AG8: =IF(Downloads_maandcijfers!AG11="", "", Downloads_maandcijfers!AG11) | AH8: =IF(Downloads_maandcijfers!AH11="", "", Downloads_maandcijfers!AH11) -> 9.5625 | AI8: =IF(Downloads_maandcijfers!AI11="", "", Downloads_maandcijfers!AI11) | AJ8: =IF(Downloads_maandcijfers!AJ11="", "", Downloads_maandcijfers!AJ11) | AK8: =IF(Downloads_maandcijfers!AK11="", "", Downloads_maandcijfers!AK11) | ... CF8: =IF(Downloads_maandcijfers!CF11="", "", Downloads_maandcijfers!CF11)
A9: 30529 | B9: =IF(Downloads_maandcijfers!B12="", "", Downloads_maandcijfers!B12) | C9: =IF(Downloads_maandcijfers!C12="", "", Downloads_maandcijfers!C12) -> 1.1868 | D9: =IF(Downloads_maandcijfers!D12="", "", Downloads_maandcijfers!D12) | E9: =IF(Downloads_maandcijfers!E12="", "", Downloads_maandcijfers!E12) | F9: =IF(Downloads_maandcijfers!F12="", "", Downloads_maandcijfers!F12) | G9: =IF(Downloads_maandcijfers!G12="", "", Downloads_maandcijfers!G12) -> 8.37 | H9: =IF(Downloads_maandcijfers!H12="", "", Downloads_maandcijfers!H12) -> 11.98 | I9: =IF(Downloads_maandcijfers!I12="", "", Downloads_maandcijfers!I12) | ... AB9: =IF(Downloads_maandcijfers!AB12="", "", Downloads_maandcijfers!AB12) | AC9: 63.79 | AD9: =IF(Downloads_maandcijfers!AD12="", "", Downloads_maandcijfers!AD12) -> 164.4 | AE9: =IF(Downloads_maandcijfers!AE12="", "", Downloads_maandcijfers!AE12) -> 177.3121 | AF9: =IF(Downloads_maandcijfers!AF12="", "", Downloads_maandcijfers!AF12) -> 9.5 | AG9: =IF(Downloads_maandcijfers!AG12="", "", Downloads_maandcijfers!AG12) | AH9: =IF(Downloads_maandcijfers!AH12="", "", Downloads_maandcijfers!AH12) -> 9.5625 | AI9: =IF(Downloads_maandcijfers!AI12="", "", Downloads_maandcijfers!AI12) | AJ9: =IF(Downloads_maandcijfers!AJ12="", "", Downloads_maandcijfers!AJ12) | AK9: =IF(Downloads_maandcijfers!AK12="", "", Downloads_maandcijfers!AK12) | ... CF9: =IF(Downloads_maandcijfers!CF12="", "", Downloads_maandcijfers!CF12)
A10: 30560 | B10: =IF(Downloads_maandcijfers!B13="", "", Downloads_maandcijfers!B13) | C10: =IF(Downloads_maandcijfers!C13="", "", Downloads_maandcijfers!C13) -> 1.1636 | D10: =IF(Downloads_maandcijfers!D13="", "", Downloads_maandcijfers!D13) | E10: =IF(Downloads_maandcijfers!E13="", "", Downloads_maandcijfers!E13) | F10: =IF(Downloads_maandcijfers!F13="", "", Downloads_maandcijfers!F13) | G10: =IF(Downloads_maandcijfers!G13="", "", Downloads_maandcijfers!G13) -> 8.48 | H10: =IF(Downloads_maandcijfers!H13="", "", Downloads_maandcijfers!H13) -> 11.44 | I10: =IF(Downloads_maandcijfers!I13="", "", Downloads_maandcijfers!I13) | ... AB10: =IF(Downloads_maandcijfers!AB13="", "", Downloads_maandcijfers!AB13) | AC10: 66.96 | AD10: =IF(Downloads_maandcijfers!AD13="", "", Downloads_maandcijfers!AD13) -> 166.07 | AE10: =IF(Downloads_maandcijfers!AE13="", "", Downloads_maandcijfers!AE13) -> 180.4669 | AF10: =IF(Downloads_maandcijfers!AF13="", "", Downloads_maandcijfers!AF13) -> 9.375 | AG10: =IF(Downloads_maandcijfers!AG13="", "", Downloads_maandcijfers!AG13) | AH10: =IF(Downloads_maandcijfers!AH13="", "", Downloads_maandcijfers!AH13) -> 9.5625 | AI10: =IF(Downloads_maandcijfers!AI13="", "", Downloads_maandcijfers!AI13) | AJ10: =IF(Downloads_maandcijfers!AJ13="", "", Downloads_maandcijfers!AJ13) | AK10: =IF(Downloads_maandcijfers!AK13="", "", Downloads_maandcijfers!AK13) | ... CF10: =IF(Downloads_maandcijfers!CF13="", "", Downloads_maandcijfers!CF13)
A11: 30590 | B11: =IF(Downloads_maandcijfers!B14="", "", Downloads_maandcijfers!B14) | C11: =IF(Downloads_maandcijfers!C14="", "", Downloads_maandcijfers!C14) -> 1.1641 | D11: =IF(Downloads_maandcijfers!D14="", "", Downloads_maandcijfers!D14) | E11: =IF(Downloads_maandcijfers!E14="", "", Downloads_maandcijfers!E14) | F11: =IF(Downloads_maandcijfers!F14="", "", Downloads_maandcijfers!F14) | G11: =IF(Downloads_maandcijfers!G14="", "", Downloads_maandcijfers!G14) -> 8.26 | H11: =IF(Downloads_maandcijfers!H14="", "", Downloads_maandcijfers!H14) -> 11.74 | I11: =IF(Downloads_maandcijfers!I14="", "", Downloads_maandcijfers!I14) | ... AB11: =IF(Downloads_maandcijfers!AB14="", "", Downloads_maandcijfers!AB14) | AC11: 64.14 | AD11: =IF(Downloads_maandcijfers!AD14="", "", Downloads_maandcijfers!AD14) -> 163.55 | AE11: =IF(Downloads_maandcijfers!AE14="", "", Downloads_maandcijfers!AE14) -> 177.9077 | AF11: =IF(Downloads_maandcijfers!AF14="", "", Downloads_maandcijfers!AF14) -> 9.375 | AG11: =IF(Downloads_maandcijfers!AG14="", "", Downloads_maandcijfers!AG14) | AH11: =IF(Downloads_maandcijfers!AH14="", "", Downloads_maandcijfers!AH14) -> 9.0625 | AI11: =IF(Downloads_maandcijfers!AI14="", "", Downloads_maandcijfers!AI14) | AJ11: =IF(Downloads_maandcijfers!AJ14="", "", Downloads_maandcijfers!AJ14) | AK11: =IF(Downloads_maandcijfers!AK14="", "", Downloads_maandcijfers!AK14) | ... CF11: =IF(Downloads_maandcijfers!CF14="", "", Downloads_maandcijfers!CF14)
A12: 30621 | B12: =IF(Downloads_maandcijfers!B15="", "", Downloads_maandcijfers!B15) | C12: =IF(Downloads_maandcijfers!C15="", "", Downloads_maandcijfers!C15) -> 1.1928 | D12: =IF(Downloads_maandcijfers!D15="", "", Downloads_maandcijfers!D15) | E12: =IF(Downloads_maandcijfers!E15="", "", Downloads_maandcijfers!E15) | F12: =IF(Downloads_maandcijfers!F15="", "", Downloads_maandcijfers!F15) | G12: =IF(Downloads_maandcijfers!G15="", "", Downloads_maandcijfers!G15) -> 8.31 | H12: =IF(Downloads_maandcijfers!H15="", "", Downloads_maandcijfers!H15) -> 11.63 | I12: =IF(Downloads_maandcijfers!I15="", "", Downloads_maandcijfers!I15) | ... AB12: =IF(Downloads_maandcijfers!AB15="", "", Downloads_maandcijfers!AB15) | AC12: 69.45 | AD12: =IF(Downloads_maandcijfers!AD15="", "", Downloads_maandcijfers!AD15) -> 166.4 | AE12: =IF(Downloads_maandcijfers!AE15="", "", Downloads_maandcijfers!AE15) -> 182.0605 | AF12: =IF(Downloads_maandcijfers!AF15="", "", Downloads_maandcijfers!AF15) -> 9.375 | AG12: =IF(Downloads_maandcijfers!AG15="", "", Downloads_maandcijfers!AG15) | AH12: =IF(Downloads_maandcijfers!AH15="", "", Downloads_maandcijfers!AH15) -> 9.0625 | AI12: =IF(Downloads_maandcijfers!AI15="", "", Downloads_maandcijfers!AI15) | AJ12: =IF(Downloads_maandcijfers!AJ15="", "", Downloads_maandcijfers!AJ15) | AK12: =IF(Downloads_maandcijfers!AK15="", "", Downloads_maandcijfers!AK15) | ... CF12: =IF(Downloads_maandcijfers!CF15="", "", Downloads_maandcijfers!CF15)
A13: 30651 | B13: =IF(Downloads_maandcijfers!B16="", "", Downloads_maandcijfers!B16) | C13: =IF(Downloads_maandcijfers!C16="", "", Downloads_maandcijfers!C16) -> 1.2086 | D13: =IF(Downloads_maandcijfers!D16="", "", Downloads_maandcijfers!D16) | E13: =IF(Downloads_maandcijfers!E16="", "", Downloads_maandcijfers!E16) | F13: =IF(Downloads_maandcijfers!F16="", "", Downloads_maandcijfers!F16) | G13: =IF(Downloads_maandcijfers!G16="", "", Downloads_maandcijfers!G16) -> 8.41 | H13: =IF(Downloads_maandcijfers!H16="", "", Downloads_maandcijfers!H16) -> 11.82 | I13: =IF(Downloads_maandcijfers!I16="", "", Downloads_maandcijfers!I16) | ... AB13: =IF(Downloads_maandcijfers!AB16="", "", Downloads_maandcijfers!AB16) | AC13: 73.22 | AD13: =IF(Downloads_maandcijfers!AD16="", "", Downloads_maandcijfers!AD16) -> 164.93 | AE13: =IF(Downloads_maandcijfers!AE16="", "", Downloads_maandcijfers!AE16) -> 183.952 | AF13: =IF(Downloads_maandcijfers!AF16="", "", Downloads_maandcijfers!AF16) -> 9.375 | AG13: =IF(Downloads_maandcijfers!AG16="", "", Downloads_maandcijfers!AG16) | AH13: =IF(Downloads_maandcijfers!AH16="", "", Downloads_maandcijfers!AH16) -> 9.0625 | AI13: =IF(Downloads_maandcijfers!AI16="", "", Downloads_maandcijfers!AI16) | AJ13: =IF(Downloads_maandcijfers!AJ16="", "", Downloads_maandcijfers!AJ16) | AK13: =IF(Downloads_maandcijfers!AK16="", "", Downloads_maandcijfers!AK16) | ... CF13: =IF(Downloads_maandcijfers!CF16="", "", Downloads_maandcijfers!CF16)
... A37: 31382 | B37: =IF(Downloads_maandcijfers!B40="", "", Downloads_maandcijfers!B40) | C37: =IF(Downloads_maandcijfers!C40="", "", Downloads_maandcijfers!C40) -> 1.1262 | D37: =IF(Downloads_maandcijfers!D40="", "", Downloads_maandcijfers!D40) -> 133.24392 | E37: =IF(Downloads_maandcijfers!E40="", "", Downloads_maandcijfers!E40) | F37: =IF(Downloads_maandcijfers!F40="", "", Downloads_maandcijfers!F40) | G37: =IF(Downloads_maandcijfers!G40="", "", Downloads_maandcijfers!G40) -> 6.45 | H37: =IF(Downloads_maandcijfers!H40="", "", Downloads_maandcijfers!H40) -> 9 | I37: =IF(Downloads_maandcijfers!I40="", "", Downloads_maandcijfers!I40) | ... AB37: =IF(Downloads_maandcijfers!AB40="", "", Downloads_maandcijfers!AB40) | AC37: 121.5 | AD37: =IF(Downloads_maandcijfers!AD40="", "", Downloads_maandcijfers!AD40) -> 211.28 | AE37: =IF(Downloads_maandcijfers!AE40="", "", Downloads_maandcijfers!AE40) -> 256.5141 | AF37: =IF(Downloads_maandcijfers!AF40="", "", Downloads_maandcijfers!AF40) -> 7.75 | AG37: =IF(Downloads_maandcijfers!AG40="", "", Downloads_maandcijfers!AG40) | AH37: =IF(Downloads_maandcijfers!AH40="", "", Downloads_maandcijfers!AH40) -> 11.375 | AI37: =IF(Downloads_maandcijfers!AI40="", "", Downloads_maandcijfers!AI40) | AJ37: =IF(Downloads_maandcijfers!AJ40="", "", Downloads_maandcijfers!AJ40) | AK37: =IF(Downloads_maandcijfers!AK40="", "", Downloads_maandcijfers!AK40) | ... CF37: =IF(Downloads_maandcijfers!CF40="", "", Downloads_maandcijfers!CF40)
A38: 31413 | B38: =IF(Downloads_maandcijfers!B41="", "", Downloads_maandcijfers!B41) | C38: =IF(Downloads_maandcijfers!C41="", "", Downloads_maandcijfers!C41) -> 1.1022 | D38: =IF(Downloads_maandcijfers!D41="", "", Downloads_maandcijfers!D41) -> 155.93292 | E38: =IF(Downloads_maandcijfers!E41="", "", Downloads_maandcijfers!E41) | F38: =IF(Downloads_maandcijfers!F41="", "", Downloads_maandcijfers!F41) | G38: =IF(Downloads_maandcijfers!G41="", "", Downloads_maandcijfers!G41) -> 6.31 | H38: =IF(Downloads_maandcijfers!H41="", "", Downloads_maandcijfers!H41) -> 9.08 | I38: =IF(Downloads_maandcijfers!I41="", "", Downloads_maandcijfers!I41) | ... CF38: =IF(Downloads_maandcijfers!CF41="", "", Downloads_maandcijfers!CF41)
A39: 31444 | B39: =IF(Downloads_maandcijfers!B42="", "", Downloads_maandcijfers!B42) | C39: =IF(Downloads_maandcijfers!C42="", "", Downloads_maandcijfers!C42) -> 1.0425 | D39: =IF(Downloads_maandcijfers!D42="", "", Downloads_maandcijfers!D42) -> 159.46768 | E39: =IF(Downloads_maandcijfers!E42="", "", Downloads_maandcijfers!E42) | F39: =IF(Downloads_maandcijfers!F42="", "", Downloads_maandcijfers!F42) | G39: =IF(Downloads_maandcijfers!G42="", "", Downloads_maandcijfers!G42) -> 6.23 | H39: =IF(Downloads_maandcijfers!H42="", "", Downloads_maandcijfers!H42) -> 8.13 | I39: =IF(Downloads_maandcijfers!I42="", "", Downloads_maandcijfers!I42) | ... CF39: =IF(Downloads_maandcijfers!CF42="", "", Downloads_maandcijfers!CF42)
A40: 31472 | B40: =IF(Downloads_maandcijfers!B43="", "", Downloads_maandcijfers!B43) | C40: =IF(Downloads_maandcijfers!C43="", "", Downloads_maandcijfers!C43) -> 1.0652 | D40: =IF(Downloads_maandcijfers!D43="", "", Downloads_maandcijfers!D43) -> 160.1981 | E40: =IF(Downloads_maandcijfers!E43="", "", Downloads_maandcijfers!E43) | F40: =IF(Downloads_maandcijfers!F43="", "", Downloads_maandcijfers!F43) | G40: =IF(Downloads_maandcijfers!G43="", "", Downloads_maandcijfers!G43) -> 5.75 | H40: =IF(Downloads_maandcijfers!H43="", "", Downloads_maandcijfers!H43) -> 7.39 | I40: =IF(Downloads_maandcijfers!I43="", "", Downloads_maandcijfers!I43) | ... CF40: =IF(Downloads_maandcijfers!CF43="", "", Downloads_maandcijfers!CF43)
A41: 31503 | B41: =IF(Downloads_maandcijfers!B44="", "", Downloads_maandcijfers!B44) | C41: =IF(Downloads_maandcijfers!C44="", "", Downloads_maandcijfers!C44) -> 1.0103 | D41: =IF(Downloads_maandcijfers!D44="", "", Downloads_maandcijfers!D44) -> 150.36626 | E41: =IF(Downloads_maandcijfers!E44="", "", Downloads_maandcijfers!E44) | F41: =IF(Downloads_maandcijfers!F44="", "", Downloads_maandcijfers!F44) | G41: =IF(Downloads_maandcijfers!G44="", "", Downloads_maandcijfers!G44) -> 5.36 | H41: =IF(Downloads_maandcijfers!H44="", "", Downloads_maandcijfers!H44) -> 7.38 | I41: =IF(Downloads_maandcijfers!I44="", "", Downloads_maandcijfers!I44) | ... CF41: =IF(Downloads_maandcijfers!CF44="", "", Downloads_maandcijfers!CF44)
A42: 31533 | B42: =IF(Downloads_maandcijfers!B45="", "", Downloads_maandcijfers!B45) | C42: =IF(Downloads_maandcijfers!C45="", "", Downloads_maandcijfers!C45) -> 1.0747 | D42: =IF(Downloads_maandcijfers!D45="", "", Downloads_maandcijfers!D45) -> 132.63792 | E42: =IF(Downloads_maandcijfers!E45="", "", Downloads_maandcijfers!E45) | F42: =IF(Downloads_maandcijfers!F45="", "", Downloads_maandcijfers!F45) | G42: =IF(Downloads_maandcijfers!G45="", "", Downloads_maandcijfers!G45) -> 5.75 | H42: =IF(Downloads_maandcijfers!H45="", "", Downloads_maandcijfers!H45) -> 8.05 | I42: =IF(Downloads_maandcijfers!I45="", "", Downloads_maandcijfers!I45) | ... CF42: =IF(Downloads_maandcijfers!CF45="", "", Downloads_maandcijfers!CF45)
A43: 31564 | B43: =IF(Downloads_maandcijfers!B46="", "", Downloads_maandcijfers!B46) | C43: =IF(Downloads_maandcijfers!C46="", "", Downloads_maandcijfers!C46) -> 1.0215 | D43: =IF(Downloads_maandcijfers!D46="", "", Downloads_maandcijfers!D46) -> 122.51177 | E43: =IF(Downloads_maandcijfers!E46="", "", Downloads_maandcijfers!E46) | F43: =IF(Downloads_maandcijfers!F46="", "", Downloads_maandcijfers!F46) | G43: =IF(Downloads_maandcijfers!G46="", "", Downloads_maandcijfers!G46) -> 5.87 | H43: =IF(Downloads_maandcijfers!H46="", "", Downloads_maandcijfers!H46) -> 7.35 | I43: =IF(Downloads_maandcijfers!I46="", "", Downloads_maandcijfers!I46) | ... CF43: =IF(Downloads_maandcijfers!CF46="", "", Downloads_maandcijfers!CF46)
A44: 31594 | B44: =IF(Downloads_maandcijfers!B47="", "", Downloads_maandcijfers!B47) | C44: =IF(Downloads_maandcijfers!C47="", "", Downloads_maandcijfers!C47) -> 0.9923 | D44: =IF(Downloads_maandcijfers!D47="", "", Downloads_maandcijfers!D47) -> 132.11963 | E44: =IF(Downloads_maandcijfers!E47="", "", Downloads_maandcijfers!E47) | F44: =IF(Downloads_maandcijfers!F47="", "", Downloads_maandcijfers!F47) | G44: =IF(Downloads_maandcijfers!G47="", "", Downloads_maandcijfers!G47) -> 5.77 | H44: =IF(Downloads_maandcijfers!H47="", "", Downloads_maandcijfers!H47) -> 7.34 | I44: =IF(Downloads_maandcijfers!I47="", "", Downloads_maandcijfers!I47) | ... CF44: =IF(Downloads_maandcijfers!CF47="", "", Downloads_maandcijfers!CF47)
A45: 31625 | B45: =IF(Downloads_maandcijfers!B48="", "", Downloads_maandcijfers!B48) | C45: =IF(Downloads_maandcijfers!C48="", "", Downloads_maandcijfers!C48) -> 0.9711 | D45: =IF(Downloads_maandcijfers!D48="", "", Downloads_maandcijfers!D48) -> 127.5525 | E45: =IF(Downloads_maandcijfers!E48="", "", Downloads_maandcijfers!E48) | F45: =IF(Downloads_maandcijfers!F48="", "", Downloads_maandcijfers!F48) | G45: =IF(Downloads_maandcijfers!G48="", "", Downloads_maandcijfers!G48) -> 5.6 | H45: =IF(Downloads_maandcijfers!H48="", "", Downloads_maandcijfers!H48) -> 6.95 | I45: =IF(Downloads_maandcijfers!I48="", "", Downloads_maandcijfers!I48) | ... CF45: =IF(Downloads_maandcijfers!CF48="", "", Downloads_maandcijfers!CF48)
A46: 31656 | B46: =IF(Downloads_maandcijfers!B49="", "", Downloads_maandcijfers!B49) | C46: =IF(Downloads_maandcijfers!C49="", "", Downloads_maandcijfers!C49) -> 0.9699 | D46: =IF(Downloads_maandcijfers!D49="", "", Downloads_maandcijfers!D49) -> 132.01833 | E46: =IF(Downloads_maandcijfers!E49="", "", Downloads_maandcijfers!E49) | F46: =IF(Downloads_maandcijfers!F49="", "", Downloads_maandcijfers!F49) | G46: =IF(Downloads_maandcijfers!G49="", "", Downloads_maandcijfers!G49) -> 5.82 | H46: =IF(Downloads_maandcijfers!H49="", "", Downloads_maandcijfers!H49) -> 7.45 | I46: =IF(Downloads_maandcijfers!I49="", "", Downloads_maandcijfers!I49) | ... CF46: =IF(Downloads_maandcijfers!CF49="", "", Downloads_maandcijfers!CF49)
A47: 31686 | B47: =IF(Downloads_maandcijfers!B50="", "", Downloads_maandcijfers!B50) | C47: =IF(Downloads_maandcijfers!C50="", "", Downloads_maandcijfers!C50) -> 0.9906 | D47: =IF(Downloads_maandcijfers!D50="", "", Downloads_maandcijfers!D50) -> 111.50926 | E47: =IF(Downloads_maandcijfers!E50="", "", Downloads_maandcijfers!E50) | F47: =IF(Downloads_maandcijfers!F50="", "", Downloads_maandcijfers!F50) | G47: =IF(Downloads_maandcijfers!G50="", "", Downloads_maandcijfers!G50) -> 6.14 | H47: =IF(Downloads_maandcijfers!H50="", "", Downloads_maandcijfers!H50) -> 7.34 | I47: =IF(Downloads_maandcijfers!I50="", "", Downloads_maandcijfers!I50) | ... CF47: =IF(Downloads_maandcijfers!CF50="", "", Downloads_maandcijfers!CF50)
A48: 31717 | B48: =IF(Downloads_maandcijfers!B51="", "", Downloads_maandcijfers!B51) | C48: =IF(Downloads_maandcijfers!C51="", "", Downloads_maandcijfers!C51) -> 0.9504 | D48: =IF(Downloads_maandcijfers!D51="", "", Downloads_maandcijfers!D51) -> 115.02029 | E48: =IF(Downloads_maandcijfers!E51="", "", Downloads_maandcijfers!E51) | F48: =IF(Downloads_maandcijfers!F51="", "", Downloads_maandcijfers!F51) | G48: =IF(Downloads_maandcijfers!G51="", "", Downloads_maandcijfers!G51) -> 6.17 | H48: =IF(Downloads_maandcijfers!H51="", "", Downloads_maandcijfers!H51) -> 7.15 | I48: =IF(Downloads_maandcijfers!I51="", "", Downloads_maandcijfers!I51) | ... CF48: =IF(Downloads_maandcijfers!CF51="", "", Downloads_maandcijfers!CF51)
A49: 31747 | B49: =IF(Downloads_maandcijfers!B52="", "", Downloads_maandcijfers!B52) | C49: =IF(Downloads_maandcijfers!C52="", "", Downloads_maandcijfers!C52) -> 0.9271 | D49: =IF(Downloads_maandcijfers!D52="", "", Downloads_maandcijfers!D52) -> 108.96811 | E49: =IF(Downloads_maandcijfers!E52="", "", Downloads_maandcijfers!E52) | F49: =IF(Downloads_maandcijfers!F52="", "", Downloads_maandcijfers!F52) | G49: =IF(Downloads_maandcijfers!G52="", "", Downloads_maandcijfers!G52) -> 5.96 | H49: =IF(Downloads_maandcijfers!H52="", "", Downloads_maandcijfers!H52) -> 7.23 | I49: =IF(Downloads_maandcijfers!I52="", "", Downloads_maandcijfers!I52) | ... CF49: =IF(Downloads_maandcijfers!CF52="", "", Downloads_maandcijfers!CF52)
... A205: 36495 | B205: =IF(Downloads_maandcijfers!B208="", "", Downloads_maandcijfers!B208) -> 24.93 | C205: =IF(Downloads_maandcijfers!C208="", "", Downloads_maandcijfers!C208) -> 0.9977 | D205: =IF(Downloads_maandcijfers!D208="", "", Downloads_maandcijfers!D208) -> 83.809474 | E205: =IF(Downloads_maandcijfers!E208="", "", Downloads_maandcijfers!E208) -> 65.17728 | F205: =IF(Downloads_maandcijfers!F208="", "", Downloads_maandcijfers!F208) -> 27.41 | G205: =IF(Downloads_maandcijfers!G208="", "", Downloads_maandcijfers!G208) -> 5.15 | H205: =IF(Downloads_maandcijfers!H208="", "", Downloads_maandcijfers!H208) -> 6.45 | I205: =IF(Downloads_maandcijfers!I208="", "", Downloads_maandcijfers!I208) -> 5.61 | ... CF205: =IF(Downloads_maandcijfers!CF208="", "", Downloads_maandcijfers!CF208)
A206: 36526 | B206: =IF(Downloads_maandcijfers!B209="", "", Downloads_maandcijfers!B209) -> 27.08 | C206: =IF(Downloads_maandcijfers!C209="", "", Downloads_maandcijfers!C209) -> 1.0221 | D206: =IF(Downloads_maandcijfers!D209="", "", Downloads_maandcijfers!D209) -> 89.201543 | E206: =IF(Downloads_maandcijfers!E209="", "", Downloads_maandcijfers!E209) -> 51.95106 | F206: =IF(Downloads_maandcijfers!F209="", "", Downloads_maandcijfers!F209) -> 24.95 | G206: =IF(Downloads_maandcijfers!G209="", "", Downloads_maandcijfers!G209) -> 5.54 | H206: =IF(Downloads_maandcijfers!H209="", "", Downloads_maandcijfers!H209) -> 6.68 | I206: =IF(Downloads_maandcijfers!I209="", "", Downloads_maandcijfers!I209) -> 5.78 | ... CF206: =IF(Downloads_maandcijfers!CF209="", "", Downloads_maandcijfers!CF209) | CG206: =IF(Downloads_maandcijfers!CG3668="", "", Downloads_maandcijfers!CG3668) | CH206: =IF(Downloads_maandcijfers!CH3668="", "", Downloads_maandcijfers!CH3668) | CI206: =IF(Downloads_maandcijfers!CI3669=0, "", Downloads_maandcijfers!CI3669) | CJ206: =IF(Downloads_maandcijfers!CJ3669=0, "", Downloads_maandcijfers!CJ3669) | CK206: =IF(Downloads_maandcijfers!CK3669=0, "", Downloads_maandcijfers!CK3669) | CL206: =IF(Downloads_maandcijfers!CL3669=0, "", Downloads_maandcijfers!CL3669) | CM206: =IF(Downloads_maandcijfers!CM3669=0, "", Downloads_maandcijfers!CM3669)
A207: 36557 | B207: =IF(Downloads_maandcijfers!B210="", "", Downloads_maandcijfers!B210) -> 29.01 | C207: =IF(Downloads_maandcijfers!C210="", "", Downloads_maandcijfers!C210) -> 1.0386 | D207: =IF(Downloads_maandcijfers!D210="", "", Downloads_maandcijfers!D210) -> 77.60139 | E207: =IF(Downloads_maandcijfers!E210="", "", Downloads_maandcijfers!E210) -> 72.962877 | F207: =IF(Downloads_maandcijfers!F210="", "", Downloads_maandcijfers!F210) -> 23.37 | G207: =IF(Downloads_maandcijfers!G210="", "", Downloads_maandcijfers!G210) -> 5.51 | H207: =IF(Downloads_maandcijfers!H210="", "", Downloads_maandcijfers!H210) -> 6.42 | I207: =IF(Downloads_maandcijfers!I210="", "", Downloads_maandcijfers!I210) -> 5.76 | ... CF207: =IF(Downloads_maandcijfers!CF210="", "", Downloads_maandcijfers!CF210) | CG207: =IF(Downloads_maandcijfers!CG3669="", "", Downloads_maandcijfers!CG3669) | CH207: =IF(Downloads_maandcijfers!CH3669="", "", Downloads_maandcijfers!CH3669) | CI207: =IF(Downloads_maandcijfers!CI3670=0, "", Downloads_maandcijfers!CI3670) | CJ207: =IF(Downloads_maandcijfers!CJ3670=0, "", Downloads_maandcijfers!CJ3670) | CK207: =IF(Downloads_maandcijfers!CK3670=0, "", Downloads_maandcijfers!CK3670) | CL207: =IF(Downloads_maandcijfers!CL3670=0, "", Downloads_maandcijfers!CL3670) | CM207: =IF(Downloads_maandcijfers!CM3670=0, "", Downloads_maandcijfers!CM3670)
A208: 36586 | B208: =IF(Downloads_maandcijfers!B211="", "", Downloads_maandcijfers!B211) -> 23.98 | C208: =IF(Downloads_maandcijfers!C211="", "", Downloads_maandcijfers!C211) -> 1.0451 | D208: =IF(Downloads_maandcijfers!D211="", "", Downloads_maandcijfers!D211) -> 77.548311 | E208: =IF(Downloads_maandcijfers!E211="", "", Downloads_maandcijfers!E211) -> 75.439555 | F208: =IF(Downloads_maandcijfers!F211="", "", Downloads_maandcijfers!F211) -> 24.11 | G208: =IF(Downloads_maandcijfers!G211="", "", Downloads_maandcijfers!G211) -> 5.33 | H208: =IF(Downloads_maandcijfers!H211="", "", Downloads_maandcijfers!H211) -> 6.03 | I208: =IF(Downloads_maandcijfers!I211="", "", Downloads_maandcijfers!I211) -> 5.5 | ... CF208: =IF(Downloads_maandcijfers!CF211="", "", Downloads_maandcijfers!CF211) | CG208: =IF(Downloads_maandcijfers!CG3670="", "", Downloads_maandcijfers!CG3670) | CH208: =IF(Downloads_maandcijfers!CH3670="", "", Downloads_maandcijfers!CH3670) | CI208: =IF(Downloads_maandcijfers!CI3671=0, "", Downloads_maandcijfers!CI3671) | CJ208: =IF(Downloads_maandcijfers!CJ3671=0, "", Downloads_maandcijfers!CJ3671) | CK208: =IF(Downloads_maandcijfers!CK3671=0, "", Downloads_maandcijfers!CK3671) | CL208: =IF(Downloads_maandcijfers!CL3671=0, "", Downloads_maandcijfers!CL3671) | CM208: =IF(Downloads_maandcijfers!CM3671=0, "", Downloads_maandcijfers!CM3671)
A209: 36617 | B209: =IF(Downloads_maandcijfers!B212="", "", Downloads_maandcijfers!B212) -> 23.79 | C209: =IF(Downloads_maandcijfers!C212="", "", Downloads_maandcijfers!C212) -> 1.0974 | D209: =IF(Downloads_maandcijfers!D212="", "", Downloads_maandcijfers!D212) -> 76.059227 | E209: =IF(Downloads_maandcijfers!E212="", "", Downloads_maandcijfers!E212) -> 72.6052 | F209: =IF(Downloads_maandcijfers!F212="", "", Downloads_maandcijfers!F212) -> 26.2 | G209: =IF(Downloads_maandcijfers!G212="", "", Downloads_maandcijfers!G212) -> 5.22 | H209: =IF(Downloads_maandcijfers!H212="", "", Downloads_maandcijfers!H212) -> 6.23 | I209: =IF(Downloads_maandcijfers!I212="", "", Downloads_maandcijfers!I212) -> 5.57 | ... CF209: =IF(Downloads_maandcijfers!CF212="", "", Downloads_maandcijfers!CF212) | CG209: =IF(Downloads_maandcijfers!CG3671="", "", Downloads_maandcijfers!CG3671) | CH209: =IF(Downloads_maandcijfers!CH3671="", "", Downloads_maandcijfers!CH3671) | CI209: =IF(Downloads_maandcijfers!CI3672=0, "", Downloads_maandcijfers!CI3672) | CJ209: =IF(Downloads_maandcijfers!CJ3672=0, "", Downloads_maandcijfers!CJ3672) | CK209: =IF(Downloads_maandcijfers!CK3672=0, "", Downloads_maandcijfers!CK3672) | CL209: =IF(Downloads_maandcijfers!CL3672=0, "", Downloads_maandcijfers!CL3672) | CM209: =IF(Downloads_maandcijfers!CM3672=0, "", Downloads_maandcijfers!CM3672)
A210: 36647 | B210: =IF(Downloads_maandcijfers!B213="", "", Downloads_maandcijfers!B213) -> 29.64 | C210: =IF(Downloads_maandcijfers!C213="", "", Downloads_maandcijfers!C213) -> 1.0783 | D210: =IF(Downloads_maandcijfers!D213="", "", Downloads_maandcijfers!D213) -> 97.986201 | E210: =IF(Downloads_maandcijfers!E213="", "", Downloads_maandcijfers!E213) -> 84.041663 | F210: =IF(Downloads_maandcijfers!F213="", "", Downloads_maandcijfers!F213) -> 23.65 | G210: =IF(Downloads_maandcijfers!G213="", "", Downloads_maandcijfers!G213) -> 5.38 | H210: =IF(Downloads_maandcijfers!H213="", "", Downloads_maandcijfers!H213) -> 6.29 | I210: =IF(Downloads_maandcijfers!I213="", "", Downloads_maandcijfers!I213) -> 5.57 | ... CF210: =IF(Downloads_maandcijfers!CF213="", "", Downloads_maandcijfers!CF213) | CG210: =IF(Downloads_maandcijfers!CG3672="", "", Downloads_maandcijfers!CG3672) | CH210: =IF(Downloads_maandcijfers!CH3672="", "", Downloads_maandcijfers!CH3672) | CI210: =IF(Downloads_maandcijfers!CI3673=0, "", Downloads_maandcijfers!CI3673) | CJ210: =IF(Downloads_maandcijfers!CJ3673=0, "", Downloads_maandcijfers!CJ3673) | CK210: =IF(Downloads_maandcijfers!CK3673=0, "", Downloads_maandcijfers!CK3673) | CL210: =IF(Downloads_maandcijfers!CL3673=0, "", Downloads_maandcijfers!CL3673) | CM210: =IF(Downloads_maandcijfers!CM3673=0, "", Downloads_maandcijfers!CM3673)
A211: 36678 | B211: =IF(Downloads_maandcijfers!B214="", "", Downloads_maandcijfers!B214) -> 31.58 | C211: =IF(Downloads_maandcijfers!C214="", "", Downloads_maandcijfers!C214) -> 1.0432 | D211: =IF(Downloads_maandcijfers!D214="", "", Downloads_maandcijfers!D214) -> 92.965017 | E211: =IF(Downloads_maandcijfers!E214="", "", Downloads_maandcijfers!E214) -> 59.968966 | F211: =IF(Downloads_maandcijfers!F214="", "", Downloads_maandcijfers!F214) -> 19.54 | G211: =IF(Downloads_maandcijfers!G214="", "", Downloads_maandcijfers!G214) -> 5.19 | H211: =IF(Downloads_maandcijfers!H214="", "", Downloads_maandcijfers!H214) -> 6.03 | I211: =IF(Downloads_maandcijfers!I214="", "", Downloads_maandcijfers!I214) -> 5.56 | ... CF211: =IF(Downloads_maandcijfers!CF214="", "", Downloads_maandcijfers!CF214) | CG211: =IF(Downloads_maandcijfers!CG3673="", "", Downloads_maandcijfers!CG3673) | CH211: =IF(Downloads_maandcijfers!CH3673="", "", Downloads_maandcijfers!CH3673) | CI211: =IF(Downloads_maandcijfers!CI3674=0, "", Downloads_maandcijfers!CI3674) | CJ211: =IF(Downloads_maandcijfers!CJ3674=0, "", Downloads_maandcijfers!CJ3674) | CK211: =IF(Downloads_maandcijfers!CK3674=0, "", Downloads_maandcijfers!CK3674) | CL211: =IF(Downloads_maandcijfers!CL3674=0, "", Downloads_maandcijfers!CL3674) | CM211: =IF(Downloads_maandcijfers!CM3674=0, "", Downloads_maandcijfers!CM3674)
A212: 36708 | B212: =IF(Downloads_maandcijfers!B215="", "", Downloads_maandcijfers!B215) -> 25.3 | C212: =IF(Downloads_maandcijfers!C215="", "", Downloads_maandcijfers!C215) -> 1.0792 | D212: =IF(Downloads_maandcijfers!D215="", "", Downloads_maandcijfers!D215) -> 79.446971 | E212: =IF(Downloads_maandcijfers!E215="", "", Downloads_maandcijfers!E215) -> 58.438124 | F212: =IF(Downloads_maandcijfers!F215="", "", Downloads_maandcijfers!F215) -> 20.74 | G212: =IF(Downloads_maandcijfers!G215="", "", Downloads_maandcijfers!G215) -> 5.27 | H212: =IF(Downloads_maandcijfers!H215="", "", Downloads_maandcijfers!H215) -> 6.04 | I212: =IF(Downloads_maandcijfers!I215="", "", Downloads_maandcijfers!I215) -> 5.55 | ... CF212: =IF(Downloads_maandcijfers!CF215="", "", Downloads_maandcijfers!CF215) | CG212: =IF(Downloads_maandcijfers!CG3674="", "", Downloads_maandcijfers!CG3674) | CH212: =IF(Downloads_maandcijfers!CH3674="", "", Downloads_maandcijfers!CH3674) | CI212: =IF(Downloads_maandcijfers!CI3675=0, "", Downloads_maandcijfers!CI3675) | CJ212: =IF(Downloads_maandcijfers!CJ3675=0, "", Downloads_maandcijfers!CJ3675) | CK212: =IF(Downloads_maandcijfers!CK3675=0, "", Downloads_maandcijfers!CK3675) | CL212: =IF(Downloads_maandcijfers!CL3675=0, "", Downloads_maandcijfers!CL3675) | CM212: =IF(Downloads_maandcijfers!CM3675=0, "", Downloads_maandcijfers!CM3675)
